Workbook

Sheet Start
B2: myTutor manual baseline test
B3: Follow the Steps sheet from top to bottom. Tick each step as you finish it.
B5: Test settings
B6: Course code | C6: <COURSE CODE>
B7: Day | C7: <Day N>
B8: Date | C8: <YYYY-MM-DD>
B9: AI chat used | C9: <AI chat app>
B11: Test folder in the vault | C11: =C6&"/"&C7&"/Baseline"
B13: Legend
B14: Yellow cell | C14: You type here. Everything else fills itself.
B15: ▶ / ■ | C15: Start / stop the stopwatch at this step
B16: Timed? | C16: Yes = inside the stopwatch time; No = before or after it
B18: Sheets
B19: Steps | C19: The test, step by step, with tick boxes for files 1 to 5
B20: Prompt | C20: Fill 3 yellow cells; copy the finished prompt into the AI chat
B21: Log | C21: One row per file per method; formulas do the maths
B22: Summary | C22: KPI averages and % change, filled automatically

Sheet Steps
A1: Part | B1: Step | C1: What to do | D1: How / detail | E1: Timed? | F1: File 1 | G1: File 2 | H1: File 3 | I1: File 4 | J1: File 5
A2: Part A: Set up once (not timed) — tick under File 1
A3: A | B3: A1 | C3: Fill the test settings | D3: On the Start sheet, fill the yellow cells: course code, day, date. | E3: No
A4: A | B4: A2 | C4: Save the 5 test files | D4: Download the 5 files for the day into one local folder. Downloading is not timed (it is the same with myTutor). | E4: No
A5: A | B5: A3 | C5: Fix the order | D5: Type the 5 file names into the Log sheet, File column, rows File 1 to File 5. Do not change the order later. | E5: No
A6: A | B6: A4 | C6: Open the tools | D6: Open the AI chat (see Start sheet), Obsidian with your vault, and a stopwatch. | E6: No
A7: A | B7: A5 | C7: Create the test folder | D7: ="In Obsidian create the folder "&Start!$C$11&" with four sub-folders: Ref, Core, Cases, Quizzes." | E7: No
A8: A | B8: A6 | C8: Keep myTutor's notes closed | D8: Do not open myTutor's notes for these 5 files until Part D. Seeing them first would make the manual run quicker than normal. | E8: No
A9: Part B: Manual run — repeat for each file, tick each file's column
A10: B | B10: B1 | C10: Set up the prompt | D10: Prompt sheet: type the File name and Type (slides / reading / case). | E10: No
A11: B | B11: B2 | C11: Start a new chat | D11: New chat in the AI app, so nothing carries over from the last file. | E11: No
A12: B | B12: B3 | C12: ▶ Start the stopwatch | D12: Start it as you open the file from your local folder. | E12: Yes
A13: B | B13: B4 | C13: List what to take notes on | D13: Skim the file only as far as needed. Type 3 to 6 key concepts (the file's own names) into the Prompt sheet's Concepts cell. Add 'Case: name' only if the file discusses a real organisation in depth. Concepts already in the vault still go on the list. | E13: Yes
A14: B | B14: B5 | C14: Send the prompt | D14: Upload the file to the chat. On the Prompt sheet select C11:C50, copy, paste into the chat, send. | E14: Yes
A15: B | B15: B6 | C15: Wait for the answer | D15: If the reply is cut off or wrong, ask it to continue or fix it. Keep the stopwatch running; note it in Log > Comments. | E15: Yes
A16: B | B16: B7 | C16: Create the Ref note | D16: In Baseline/Ref, name it after the file. Paste the reference note. Add a link to the original file on its first line. | E16: Yes
A17: B | B17: B8 | C17: Create or link Core notes | D17: For each concept, first search the vault (Ctrl+O). Note already exists: link to it, do not create a new one. Otherwise create it in Baseline/Core, named in title case. | E17: Yes
A18: B | B18: B9 | C18: Create the Case note | D18: Only if the file has a case: in Baseline/Cases, named 'Case - Organisation'. | E18: Yes
A19: B | B19: B10 | C19: Create the Quiz note | D19: In Baseline/Quizzes, named 'Quiz - <course> <day> - <file title>'. | E19: Yes
A20: B | B20: B11 | C20: Check the links | D20: Ref links to every new note; every new note links back to Ref and to at least one existing note. Tip: Backlinks > Unlinked mentions > Link. | E20: Yes
A21: B | B21: B12 | C21: Read every note once | D21: Fix anything clearly wrong. | E21: Yes
... A23: B | B23: B14 | C23: Log the file | D23: Log sheet, Manual row for this file: minutes, notes created, notes passing all 5 checks, links to existing notes, checks 1 to 5. Then repeat B1 to B14 for the next file. | E23: No
A24: Part D/E: myTutor on the same 5 files — tick each file's column
A25: D | B25: D1 | C25: Run myTutor on the same files | D25: Only if not yet run: drop the 5 files in the OneDrive MyTutor folder and let it run (or run py run.py). Do not open the notes yet. | E25: No
A26: D | B26: D2 | C26: Note myTutor's run time and words | D26: From the myTutor log, copy each file's run minutes and word count into the Log sheet (both rows of that file get the word count). | E26: No
A27: D | B27: D3 | C27: ▶ Start the stopwatch | D27: Open myTutor's notes for the file in the vault, then start. | E27: Yes
A28: D | B28: D4 | C28: Read and fix | D28: Read every note for that file once and fix anything clearly wrong, as in B12. | E28: Yes
A29: D | B29: D5 | C29: ■ Stop the stopwatch | E29: Yes
A30: D | B30: D6 | C30: Log the file | D30: Log sheet, myTutor row: review minutes, notes created, notes passing all 5 checks, links, checks 1 to 5. Repeat D3 to D6 for each file. | E30: No
A31: E | B31: E1 | C31: Read the results | D31: The Summary sheet now shows the averages and % change. Copy them into the final deck. | E31: No
A32: The 5 quality checks (used in B14 and D6)
A33: C | B33: C1 | C33: Check 1: right folder | D33: Every note is in the correct sub-folder (Ref, Core, Cases, Quizzes).
A34: C | B34: C2 | C34: Check 2: frontmatter complete | D34: Every field in the template is filled in.
A35: C | B35: C3 | C35: Check 3: links to original | D35: The Ref note links to the original file.
A36: C | B36: C4 | C36: Check 4: links to existing note | D36: Each new note links to at least one note that was already in the vault.
A37: C | B37: C5 | C37: Check 5: no errors | D37: Nothing contradicts the file. Spot-check each note against it.

Sheet Prompt
B2: Prompt for the current file
B3: Change the 3 yellow cells for each file. Then select C11:C50, copy, and paste into the AI chat.
B5: File name | C5: <file name>
B6: Type | C6: <slides / reading / case>
B7: Concepts I want covered | C7: <3 to 6 concepts, comma separated>
B9: Finished prompt (copy C11:C50)
C11: =SUBSTITUTE(SUBSTITUTE(SUBSTITUTE(SUBSTITUTE(SUBSTITUTE(SUBSTITUTE($E11,"{COURSE}",Start!$C$6),"{DAY}",Start!$C$7),"{DATE}",IF(ISNUMBER(Start!$C$8),TEXT(Start!$C$8,"yyyy-mm-dd"),Start!$C$8)),"{FILE}",$C$5),"{KIND}",$C$6),"{CONCEPTS}",$C$7) | E11: I am attaching one source for my MBA course. Turn it into Obsidian notes in Markdown.
C12: =SUBSTITUTE(SUBSTITUTE(SUBSTITUTE(SUBSTITUTE(SUBSTITUTE(SUBSTITUTE($E12,"{COURSE}",Start!$C$6),"{DAY}",Start!$C$7),"{DATE}",IF(ISNUMBER(Start!$C$8),TEXT(Start!$C$8,"yyyy-mm-dd"),Start!$C$8)),"{FILE}",$C$5),"{KIND}",$C$6),"{CONCEPTS}",$C$7)
C13: =SUBSTITUTE(SUBSTITUTE(SUBSTITUTE(SUBSTITUTE(SUBSTITUTE(SUBSTITUTE($E13,"{COURSE}",Start!$C$6),"{DAY}",Start!$C$7),"{DATE}",IF(ISNUMBER(Start!$C$8),TEXT(Start!$C$8,"yyyy-mm-dd"),Start!$C$8)),"{FILE}",$C$5),"{KIND}",$C$6),"{CONCEPTS}",$C$7) | E13: Course: {COURSE} Day: {DAY} Date: {DATE}
C14: =SUBSTITUTE(SUBSTITUTE(SUBSTITUTE(SUBSTITUTE(SUBSTITUTE(SUBSTITUTE($E14,"{COURSE}",Start!$C$6),"{DAY}",Start!$C$7),"{DATE}",IF(ISNUMBER(Start!$C$8),TEXT(Start!$C$8,"yyyy-mm-dd"),Start!$C$8)),"{FILE}",$C$5),"{KIND}",$C$6),"{CONCEPTS}",$C$7) | E14: Source file: {FILE}
C15: =SUBSTITUTE(SUBSTITUTE(SUBSTITUTE(SUBSTITUTE(SUBSTITUTE(SUBSTITUTE($E15,"{COURSE}",Start!$C$6),"{DAY}",Start!$C$7),"{DATE}",IF(ISNUMBER(Start!$C$8),TEXT(Start!$C$8,"yyyy-mm-dd"),Start!$C$8)),"{FILE}",$C$5),"{KIND}",$C$6),"{CONCEPTS}",$C$7) | E15: Concepts I want covered: {CONCEPTS}
C16: =SUBSTITUTE(SUBSTITUTE(SUBSTITUTE(SUBSTITUTE(SUBSTITUTE(SUBSTITUTE($E16,"{COURSE}",Start!$C$6),"{DAY}",Start!$C$7),"{DATE}",IF(ISNUMBER(Start!$C$8),TEXT(Start!$C$8,"yyyy-mm-dd"),Start!$C$8)),"{FILE}",$C$5),"{KIND}",$C$6),"{CONCEPTS}",$C$7)
C17: =SUBSTITUTE(SUBSTITUTE(SUBSTITUTE(SUBSTITUTE(SUBSTITUTE(SUBSTITUTE($E17,"{COURSE}",Start!$C$6),"{DAY}",Start!$C$7),"{DATE}",IF(ISNUMBER(Start!$C$8),TEXT(Start!$C$8,"yyyy-mm-dd"),Start!$C$8)),"{FILE}",$C$5),"{KIND}",$C$6),"{CONCEPTS}",$C$7) | E17: Write these notes. Put each note in its own code block, with its file name on the line above the block.
C18: =SUBSTITUTE(SUBSTITUTE(SUBSTITUTE(SUBSTITUTE(SUBSTITUTE(SUBSTITUTE($E18,"{COURSE}",Start!$C$6),"{DAY}",Start!$C$7),"{DATE}",IF(ISNUMBER(Start!$C$8),TEXT(Start!$C$8,"yyyy-mm-dd"),Start!$C$8)),"{FILE}",$C$5),"{KIND}",$C$6),"{CONCEPTS}",$C$7)
C19: =SUBSTITUTE(SUBSTITUTE(SUBSTITUTE(SUBSTITUTE(SUBSTITUTE(SUBSTITUTE($E19,"{COURSE}",Start!$C$6),"{DAY}",Start!$C$7),"{DATE}",IF(ISNUMBER(Start!$C$8),TEXT(Start!$C$8,"yyyy-mm-dd"),Start!$C$8)),"{FILE}",$C$5),"{KIND}",$C$6),"{CONCEPTS}",$C$7) | E19: 1. ONE reference note, named after the source.
C20: =SUBSTITUTE(SUBSTITUTE(SUBSTITUTE(SUBSTITUTE(SUBSTITUTE(SUBSTITUTE($E20,"{COURSE}",Start!$C$6),"{DAY}",Start!$C$7),"{DATE}",IF(ISNUMBER(Start!$C$8),TEXT(Start!$C$8,"yyyy-mm-dd"),Start!$C$8)),"{FILE}",$C$5),"{KIND}",$C$6),"{CONCEPTS}",$C$7) | E20: Frontmatter:
C21: =SUBSTITUTE(SUBSTITUTE(SUBSTITUTE(SUBSTITUTE(SUBSTITUTE(SUBSTITUTE($E21,"{COURSE}",Start!$C$6),"{DAY}",Start!$C$7),"{DATE}",IF(ISNUMBER(Start!$C$8),TEXT(Start!$C$8,"yyyy-mm-dd"),Start!$C$8)),"{FILE}",$C$5),"{KIND}",$C$6),"{CONCEPTS}",$C$7) | E21: ---
C22: =SUBSTITUTE(SUBSTITUTE(SUBSTITUTE(SUBSTITUTE(SUBSTITUTE(SUBSTITUTE($E22,"{COURSE}",Start!$C$6),"{DAY}",Start!$C$7),"{DATE}",IF(ISNUMBER(Start!$C$8),TEXT(Start!$C$8,"yyyy-mm-dd"),Start!$C$8)),"{FILE}",$C$5),"{KIND}",$C$6),"{CONCEPTS}",$C$7) | E22: type: reference
C23: =SUBSTITUTE(SUBSTITUTE(SUBSTITUTE(SUBSTITUTE(SUBSTITUTE(SUBSTITUTE($E23,"{COURSE}",Start!$C$6),"{DAY}",Start!$C$7),"{DATE}",IF(ISNUMBER(Start!$C$8),TEXT(Start!$C$8,"yyyy-mm-dd"),Start!$C$8)),"{FILE}",$C$5),"{KIND}",$C$6),"{CONCEPTS}",$C$7) | E23: course: {COURSE}
C24: =SUBSTITUTE(SUBSTITUTE(SUBSTITUTE(SUBSTITUTE(SUBSTITUTE(SUBSTITUTE($E24,"{COURSE}",Start!$C$6),"{DAY}",Start!$C$7),"{DATE}",IF(ISNUMBER(Start!$C$8),TEXT(Start!$C$8,"yyyy-mm-dd"),Start!$C$8)),"{FILE}",$C$5),"{KIND}",$C$6),"{CONCEPTS}",$C$7) | E24: day: {DAY}
C25: =SUBSTITUTE(SUBSTITUTE(SUBSTITUTE(SUBSTITUTE(SUBSTITUTE(SUBSTITUTE($E25,"{COURSE}",Start!$C$6),"{DAY}",Start!$C$7),"{DATE}",IF(ISNUMBER(Start!$C$8),TEXT(Start!$C$8,"yyyy-mm-dd"),Start!$C$8)),"{FILE}",$C$5),"{KIND}",$C$6),"{CONCEPTS}",$C$7) | E25: kind: {KIND}
C26: =SUBSTITUTE(SUBSTITUTE(SUBSTITUTE(SUBSTITUTE(SUBSTITUTE(SUBSTITUTE($E26,"{COURSE}",Start!$C$6),"{DAY}",Start!$C$7),"{DATE}",IF(ISNUMBER(Start!$C$8),TEXT(Start!$C$8,"yyyy-mm-dd"),Start!$C$8)),"{FILE}",$C$5),"{KIND}",$C$6),"{CONCEPTS}",$C$7) | E26: source: "{FILE}"
C27: =SUBSTITUTE(SUBSTITUTE(SUBSTITUTE(SUBSTITUTE(SUBSTITUTE(SUBSTITUTE($E27,"{COURSE}",Start!$C$6),"{DAY}",Start!$C$7),"{DATE}",IF(ISNUMBER(Start!$C$8),TEXT(Start!$C$8,"yyyy-mm-dd"),Start!$C$8)),"{FILE}",$C$5),"{KIND}",$C$6),"{CONCEPTS}",$C$7) | E27: created: {DATE}
C28: =SUBSTITUTE(SUBSTITUTE(SUBSTITUTE(SUBSTITUTE(SUBSTITUTE(SUBSTITUTE($E28,"{COURSE}",Start!$C$6),"{DAY}",Start!$C$7),"{DATE}",IF(ISNUMBER(Start!$C$8),TEXT(Start!$C$8,"yyyy-mm-dd"),Start!$C$8)),"{FILE}",$C$5),"{KIND}",$C$6),"{CONCEPTS}",$C$7) | E28: tags: [reference]
C29: =SUBSTITUTE(SUBSTITUTE(SUBSTITUTE(SUBSTITUTE(SUBSTITUTE(SUBSTITUTE($E29,"{COURSE}",Start!$C$6),"{DAY}",Start!$C$7),"{DATE}",IF(ISNUMBER(Start!$C$8),TEXT(Start!$C$8,"yyyy-mm-dd"),Start!$C$8)),"{FILE}",$C$5),"{KIND}",$C$6),"{CONCEPTS}",$C$7) | E29: ---
C30: =SUBSTITUTE(SUBSTITUTE(SUBSTITUTE(SUBSTITUTE(SUBSTITUTE(SUBSTITUTE($E30,"{COURSE}",Start!$C$6),"{DAY}",Start!$C$7),"{DATE}",IF(ISNUMBER(Start!$C$8),TEXT(Start!$C$8,"yyyy-mm-dd"),Start!$C$8)),"{FILE}",$C$5),"{KIND}",$C$6),"{CONCEPTS}",$C$7) | E30: Sections: Overview (3 sentences), Key points (5 to 8, in the source's order), Frameworks and models (each linked to its core note), Questions I should be able to answer (3), Related (links to every core, case and quiz note below).
C31: =SUBSTITUTE(SUBSTITUTE(SUBSTITUTE(SUBSTITUTE(SUBSTITUTE(SUBSTITUTE($E31,"{COURSE}",Start!$C$6),"{DAY}",Start!$C$7),"{DATE}",IF(ISNUMBER(Start!$C$8),TEXT(Start!$C$8,"yyyy-mm-dd"),Start!$C$8)),"{FILE}",$C$5),"{KIND}",$C$6),"{CONCEPTS}",$C$7)
C32: =SUBSTITUTE(SUBSTITUTE(SUBSTITUTE(SUBSTITUTE(SUBSTITUTE(SUBSTITUTE($E32,"{COURSE}",Start!$C$6),"{DAY}",Start!$C$7),"{DATE}",IF(ISNUMBER(Start!$C$8),TEXT(Start!$C$8,"yyyy-mm-dd"),Start!$C$8)),"{FILE}",$C$5),"{KIND}",$C$6),"{CONCEPTS}",$C$7) | E32: 2. THREE TO SIX core notes, one per concept from my list, named after the concept in title case.
C33: =SUBSTITUTE(SUBSTITUTE(SUBSTITUTE(SUBSTITUTE(SUBSTITUTE(SUBSTITUTE($E33,"{COURSE}",Start!$C$6),"{DAY}",Start!$C$7),"{DATE}",IF(ISNUMBER(Start!$C$8),TEXT(Start!$C$8,"yyyy-mm-dd"),Start!$C$8)),"{FILE}",$C$5),"{KIND}",$C$6),"{CONCEPTS}",$C$7) | E33: Frontmatter: type: core, course: {COURSE}, first_seen: "{FILE}", created: {DATE}, tags: [core]
C34: =SUBSTITUTE(SUBSTITUTE(SUBSTITUTE(SUBSTITUTE(SUBSTITUTE(SUBSTITUTE($E34,"{COURSE}",Start!$C$6),"{DAY}",Start!$C$7),"{DATE}",IF(ISNUMBER(Start!$C$8),TEXT(Start!$C$8,"yyyy-mm-dd"),Start!$C$8)),"{FILE}",$C$5),"{KIND}",$C$6),"{CONCEPTS}",$C$7) | E34: Body: Definition, Why it matters, Example from the source, Related concepts, Cases that illustrate it, Source: [[<reference note title>]]. Under 200 words each.
C35: =SUBSTITUTE(SUBSTITUTE(SUBSTITUTE(SUBSTITUTE(SUBSTITUTE(SUBSTITUTE($E35,"{COURSE}",Start!$C$6),"{DAY}",Start!$C$7),"{DATE}",IF(ISNUMBER(Start!$C$8),TEXT(Start!$C$8,"yyyy-mm-dd"),Start!$C$8)),"{FILE}",$C$5),"{KIND}",$C$6),"{CONCEPTS}",$C$7)
C36: =SUBSTITUTE(SUBSTITUTE(SUBSTITUTE(SUBSTITUTE(SUBSTITUTE(SUBSTITUTE($E36,"{COURSE}",Start!$C$6),"{DAY}",Start!$C$7),"{DATE}",IF(ISNUMBER(Start!$C$8),TEXT(Start!$C$8,"yyyy-mm-dd"),Start!$C$8)),"{FILE}",$C$5),"{KIND}",$C$6),"{CONCEPTS}",$C$7) | E36: 3. ONE case note per real organisation discussed as a case, ONLY if the source has one. Name: "Case - <Organisation>".
C37: =SUBSTITUTE(SUBSTITUTE(SUBSTITUTE(SUBSTITUTE(SUBSTITUTE(SUBSTITUTE($E37,"{COURSE}",Start!$C$6),"{DAY}",Start!$C$7),"{DATE}",IF(ISNUMBER(Start!$C$8),TEXT(Start!$C$8,"yyyy-mm-dd"),Start!$C$8)),"{FILE}",$C$5),"{KIND}",$C$6),"{CONCEPTS}",$C$7) | E37: Frontmatter: type: case, course: {COURSE}, day: {DAY}, organisation, source: "{FILE}", created: {DATE}, tags: [case]
C38: =SUBSTITUTE(SUBSTITUTE(SUBSTITUTE(SUBSTITUTE(SUBSTITUTE(SUBSTITUTE($E38,"{COURSE}",Start!$C$6),"{DAY}",Start!$C$7),"{DATE}",IF(ISNUMBER(Start!$C$8),TEXT(Start!$C$8,"yyyy-mm-dd"),Start!$C$8)),"{FILE}",$C$5),"{KIND}",$C$6),"{CONCEPTS}",$C$7) | E38: Body: Context, Problem, What they did, Outcome, Concepts illustrated, Source.
C39: =SUBSTITUTE(SUBSTITUTE(SUBSTITUTE(SUBSTITUTE(SUBSTITUTE(SUBSTITUTE($E39,"{COURSE}",Start!$C$6),"{DAY}",Start!$C$7),"{DATE}",IF(ISNUMBER(Start!$C$8),TEXT(Start!$C$8,"yyyy-mm-dd"),Start!$C$8)),"{FILE}",$C$5),"{KIND}",$C$6),"{CONCEPTS}",$C$7)
C40: =SUBSTITUTE(SUBSTITUTE(SUBSTITUTE(SUBSTITUTE(SUBSTITUTE(SUBSTITUTE($E40,"{COURSE}",Start!$C$6),"{DAY}",Start!$C$7),"{DATE}",IF(ISNUMBER(Start!$C$8),TEXT(Start!$C$8,"yyyy-mm-dd"),Start!$C$8)),"{FILE}",$C$5),"{KIND}",$C$6),"{CONCEPTS}",$C$7) | E40: 4. ONE quiz note, named "Quiz - {COURSE} {DAY} - <source title>".
C41: =SUBSTITUTE(SUBSTITUTE(SUBSTITUTE(SUBSTITUTE(SUBSTITUTE(SUBSTITUTE($E41,"{COURSE}",Start!$C$6),"{DAY}",Start!$C$7),"{DATE}",IF(ISNUMBER(Start!$C$8),TEXT(Start!$C$8,"yyyy-mm-dd"),Start!$C$8)),"{FILE}",$C$5),"{KIND}",$C$6),"{CONCEPTS}",$C$7) | E41: 5 multiple-choice questions testing understanding, not wording. 4 options each, one correct. Give the answer and a 1-2 sentence explanation for each, and link the core note it comes from.
C42: =SUBSTITUTE(SUBSTITUTE(SUBSTITUTE(SUBSTITUTE(SUBSTITUTE(SUBSTITUTE($E42,"{COURSE}",Start!$C$6),"{DAY}",Start!$C$7),"{DATE}",IF(ISNUMBER(Start!$C$8),TEXT(Start!$C$8,"yyyy-mm-dd"),Start!$C$8)),"{FILE}",$C$5),"{KIND}",$C$6),"{CONCEPTS}",$C$7)
C43: =SUBSTITUTE(SUBSTITUTE(SUBSTITUTE(SUBSTITUTE(SUBSTITUTE(SUBSTITUTE($E43,"{COURSE}",Start!$C$6),"{DAY}",Start!$C$7),"{DATE}",IF(ISNUMBER(Start!$C$8),TEXT(Start!$C$8,"yyyy-mm-dd"),Start!$C$8)),"{FILE}",$C$5),"{KIND}",$C$6),"{CONCEPTS}",$C$7) | E43: Rules:
C44: =SUBSTITUTE(SUBSTITUTE(SUBSTITUTE(SUBSTITUTE(SUBSTITUTE(SUBSTITUTE($E44,"{COURSE}",Start!$C$6),"{DAY}",Start!$C$7),"{DATE}",IF(ISNUMBER(Start!$C$8),TEXT(Start!$C$8,"yyyy-mm-dd"),Start!$C$8)),"{FILE}",$C$5),"{KIND}",$C$6),"{CONCEPTS}",$C$7) | E44: - Link notes to each other with [[Exact Title]].
...

Sheet Log
A1: File # | B1: Method | C1: File name | D1: Type | E1: Words | F1: Stopwatch min | G1: myTutor run min | H1: Total min | I1: Min per 1,000 words | J1: Notes created | K1: Notes passing all 5 checks | L1: Quality % | M1: Links to existing notes | N1: Links per note | O1: Check 1 folder | P1: Check 2 frontmatter | Q1: Check 3 original | R1: Check 4 existing | S1: Check 5 no errors | T1: Comments
A2: 1 | B2: Manual | H2: =IF(F2="","",F2+N(G2)) | I2: =IF(OR(H2="",N(E2)=0),"",H2/(E2/1000)) | L2: =IF(OR(N(J2)=0,K2=""),"",K2/J2) | N2: =IF(N(J2)=0,"",M2/J2)
A3: 2 | B3: Manual | H3: =IF(F3="","",F3+N(G3)) | I3: =IF(OR(H3="",N(E3)=0),"",H3/(E3/1000)) | L3: =IF(OR(N(J3)=0,K3=""),"",K3/J3) | N3: =IF(N(J3)=0,"",M3/J3)
A4: 3 | B4: Manual | H4: =IF(F4="","",F4+N(G4)) | I4: =IF(OR(H4="",N(E4)=0),"",H4/(E4/1000)) | L4: =IF(OR(N(J4)=0,K4=""),"",K4/J4) | N4: =IF(N(J4)=0,"",M4/J4)
A5: 4 | B5: Manual | H5: =IF(F5="","",F5+N(G5)) | I5: =IF(OR(H5="",N(E5)=0),"",H5/(E5/1000)) | L5: =IF(OR(N(J5)=0,K5=""),"",K5/J5) | N5: =IF(N(J5)=0,"",M5/J5)
A6: 5 | B6: Manual | H6: =IF(F6="","",F6+N(G6)) | I6: =IF(OR(H6="",N(E6)=0),"",H6/(E6/1000)) | L6: =IF(OR(N(J6)=0,K6=""),"",K6/J6) | N6: =IF(N(J6)=0,"",M6/J6)
A7: 1 | B7: myTutor | C7: =IF(C2="","",C2) | D7: =IF(D2="","",D2) | E7: =IF(E2="","",E2) | F7: =J7*0.25 | G7: =49.7/60 | H7: =IF(F7="","",F7+N(G7)) | I7: =IF(OR(H7="",N(E7)=0),"",H7/(E7/1000)) | K7: =J7 | L7: =IF(OR(N(J7)=0,K7=""),"",K7/J7) | N7: =IF(N(J7)=0,"",M7/J7)
A8: 2 | B8: myTutor | C8: =IF(C3="","",C3) | D8: =IF(D3="","",D3) | E8: =IF(E3="","",E3) | F8: =J8*0.25 | G8: =42.6/60 | H8: =IF(F8="","",F8+N(G8)) | I8: =IF(OR(H8="",N(E8)=0),"",H8/(E8/1000)) | K8: =J8 | L8: =IF(OR(N(J8)=0,K8=""),"",K8/J8) | N8: =IF(N(J8)=0,"",M8/J8)
A9: 3 | B9: myTutor | C9: =IF(C4="","",C4) | D9: =IF(D4="","",D4) | E9: =IF(E4="","",E4) | F9: =J9*0.25 | G9: =52.8/60 | H9: =IF(F9="","",F9+N(G9)) | I9: =IF(OR(H9="",N(E9)=0),"",H9/(E9/1000)) | K9: =J9 | L9: =IF(OR(N(J9)=0,K9=""),"",K9/J9) | N9: =IF(N(J9)=0,"",M9/J9)
A10: 4 | B10: myTutor | C10: =IF(C5="","",C5) | D10: =IF(D5="","",D5) | E10: =IF(E5="","",E5) | F10: =J10*0.25 | G10: =33.8/60 | H10: =IF(F10="","",F10+N(G10)) | I10: =IF(OR(H10="",N(E10)=0),"",H10/(E10/1000)) | K10: =J10 | L10: =IF(OR(N(J10)=0,K10=""),"",K10/J10) | N10: =IF(N(J10)=0,"",M10/J10)
A11: 5 | B11: myTutor | C11: =IF(C6="","",C6) | D11: =IF(D6="","",D6) | E11: =IF(E6="","",E6) | F11: =J11*0.25 | G11: =37.4/60 | H11: =IF(F11="","",F11+N(G11)) | I11: =IF(OR(H11="",N(E11)=0),"",H11/(E11/1000)) | K11: =J11 | L11: =IF(OR(N(J11)=0,K11=""),"",K11/J11) | N11: =IF(N(J11)=0,"",M11/J11)
A13: Example of a filled row (format only, not counted):
A14: 1 | B14: Manual | H14: =F14 | I14: =H14/(E14/1000) | L14: =K14/J14 | N14: =M14/J14
A16: Notes:
A17: Stopwatch min: Manual rows = whole manual run (B3 to B13). myTutor rows = your review time only (D3 to D5).
A18: myTutor run min: from the myTutor log, myTutor rows only. Total min = stopwatch + run time.
A19: Words: copy from the myTutor log. The myTutor row copies File name, Type and Words from the Manual row above.
A20: Checks: ✓ if every note of that file passes, ✗ if any fails (say which note in Comments).
A21: Yellow = you type. Grey/white = formulas, leave alone.

Sheet Column guide
B2: Log sheet: columns J to N
B3: In the myTutor rows, column K is the only one you type in.
B5: Column | C5: Meaning | D5: myTutor rows | E5: Manual rows
B6: Notes created (J) | C6: How many notes this file produced (Ref, Core, Case and Quiz notes) | D6: Already filled in from generate_runs.csv | E6: What you counted
B7: Notes passing all 5 checks (K) | C7: How many of those notes pass every check: right folder, complete frontmatter, link to the original file, link to an existing note, no errors | D7: Fills in from the Review tally sheet | E7: Already filled in
B8: Quality % (L) | C8: Notes passing ÷ notes created | D8: Calculated | E8: Calculated
B9: Links to existing notes (M) | C9: Links from this file's notes to notes that were already in the vault | D9: Already filled in from generate_runs.csv | E9: What you counted
B10: Links per note (N) | C10: Links ÷ notes created | D10: Calculated | E10: Calculated
B12: How to count column K
B13: 1. On the Review tally sheet, find each note of the file and set its File # if blank (the Core notes).
B14: 2. Open the note in Obsidian and mark the 5 checks ✓ or ✗. A note passes only if all 5 are ✓.
B15: 3. The Pass column and Log column K fill in automatically: e.g. 6 of 7 passing shows 86% Quality.
B16: 4. In Log columns O–S, mark ✓ or ✗ per check for the whole file; name any failing note in Comments.
B17: Checks 1–4 are already done for the 10 sampled notes in quality_audit.csv. The real work is check 5 (no errors): spot-check each note against the source.

Sheet Review tally
A1: File # | B1: Note title | C1: Type | D1: Check 1 folder | E1: Check 2 frontmatter | F1: Check 3 original | G1: Check 4 existing | H1: Check 5 no errors | I1: Result | J1: Comment
A2: 1 | I2: =IF(COUNTA(D2:H2)<5,"",IF(COUNTIF(D2:H2,"✓")=5,"Pass","Fail"))
A3: 1 | I3: =IF(COUNTA(D3:H3)<5,"",IF(COUNTIF(D3:H3,"✓")=5,"Pass","Fail"))
A4: 2 | I4: =IF(COUNTA(D4:H4)<5,"",IF(COUNTIF(D4:H4,"✓")=5,"Pass","Fail"))
A5: 2 | I5: =IF(COUNTA(D5:H5)<5,"",IF(COUNTIF(D5:H5,"✓")=5,"Pass","Fail"))
A6: 3 | I6: =IF(COUNTA(D6:H6)<5,"",IF(COUNTIF(D6:H6,"✓")=5,"Pass","Fail"))
A7: 3 | I7: =IF(COUNTA(D7:H7)<5,"",IF(COUNTIF(D7:H7,"✓")=5,"Pass","Fail"))
A8: 4 | I8: =IF(COUNTA(D8:H8)<5,"",IF(COUNTIF(D8:H8,"✓")=5,"Pass","Fail"))
A9: 4 | I9: =IF(COUNTA(D9:H9)<5,"",IF(COUNTIF(D9:H9,"✓")=5,"Pass","Fail"))
A10: 5 | I10: =IF(COUNTA(D10:H10)<5,"",IF(COUNTIF(D10:H10,"✓")=5,"Pass","Fail"))
A11: 5 | I11: =IF(COUNTA(D11:H11)<5,"",IF(COUNTIF(D11:H11,"✓")=5,"Pass","Fail"))
I12: =IF(COUNTA(D12:H12)<5,"",IF(COUNTIF(D12:H12,"✓")=5,"Pass","Fail"))
I13: =IF(COUNTA(D13:H13)<5,"",IF(COUNTIF(D13:H13,"✓")=5,"Pass","Fail"))
I14: =IF(COUNTA(D14:H14)<5,"",IF(COUNTIF(D14:H14,"✓")=5,"Pass","Fail"))
I15: =IF(COUNTA(D15:H15)<5,"",IF(COUNTIF(D15:H15,"✓")=5,"Pass","Fail"))
I16: =IF(COUNTA(D16:H16)<5,"",IF(COUNTIF(D16:H16,"✓")=5,"Pass","Fail"))
I17: =IF(COUNTA(D17:H17)<5,"",IF(COUNTIF(D17:H17,"✓")=5,"Pass","Fail"))
I18: =IF(COUNTA(D18:H18)<5,"",IF(COUNTIF(D18:H18,"✓")=5,"Pass","Fail"))
I19: =IF(COUNTA(D19:H19)<5,"",IF(COUNTIF(D19:H19,"✓")=5,"Pass","Fail"))
I20: =IF(COUNTA(D20:H20)<5,"",IF(COUNTIF(D20:H20,"✓")=5,"Pass","Fail"))
I21: =IF(COUNTA(D21:H21)<5,"",IF(COUNTIF(D21:H21,"✓")=5,"Pass","Fail"))
I22: =IF(COUNTA(D22:H22)<5,"",IF(COUNTIF(D22:H22,"✓")=5,"Pass","Fail"))
I23: =IF(COUNTA(D23:H23)<5,"",IF(COUNTIF(D23:H23,"✓")=5,"Pass","Fail"))
... I35: =IF(COUNTA(D35:H35)<5,"",IF(COUNTIF(D35:H35,"✓")=5,"Pass","Fail"))
C42: =COUNTIF($A$2:$A$35,1) | D42: =COUNTIFS($A$2:$A$35,1,$I$2:$I$35,"?*") | E42: =COUNTIFS($A$2:$A$35,1,$I$2:$I$35,"Pass")
C43: =COUNTIF($A$2:$A$35,2) | D43: =COUNTIFS($A$2:$A$35,2,$I$2:$I$35,"?*") | E43: =COUNTIFS($A$2:$A$35,2,$I$2:$I$35,"Pass")
C44: =COUNTIF($A$2:$A$35,3) | D44: =COUNTIFS($A$2:$A$35,3,$I$2:$I$35,"?*") | E44: =COUNTIFS($A$2:$A$35,3,$I$2:$I$35,"Pass")
C45: =COUNTIF($A$2:$A$35,4) | D45: =COUNTIFS($A$2:$A$35,4,$I$2:$I$35,"?*") | E45: =COUNTIFS($A$2:$A$35,4,$I$2:$I$35,"Pass")
C46: =COUNTIF($A$2:$A$35,5) | D46: =COUNTIFS($A$2:$A$35,5,$I$2:$I$35,"?*") | E46: =COUNTIFS($A$2:$A$35,5,$I$2:$I$35,"Pass")

Sheet Summary
B2: Results: manual vs myTutor (same 5 files)
B4: KPI | C4: Manual | D4: myTutor | E4: % change | F4: Better when
B5: Time: min per 1,000 words (total min ÷ total words) | C5: =IFERROR(SUMIFS(Log!$H$2:$H$11,Log!$B$2:$B$11,"Manual")/SUMIFS(Log!$E$2:$E$11,Log!$B$2:$B$11,"Manual")*1000,"") | D5: =IFERROR(SUMIFS(Log!$H$2:$H$11,Log!$B$2:$B$11,"myTutor")/SUMIFS(Log!$E$2:$E$11,Log!$B$2:$B$11,"myTutor")*1000,"") | E5: =IF(OR(C5="",D5="",N(C5)=0),"",(D5-C5)/C5) | F5: lower
B6: Note quality: notes passing all 5 checks | C6: =IF(SUMPRODUCT((Log!$B$2:$B$11="Manual")*(Log!$K$2:$K$11<>""))=0,"",IFERROR(SUMIFS(Log!$K$2:$K$11,Log!$B$2:$B$11,"Manual")/SUMIFS(Log!$J$2:$J$11,Log!$B$2:$B$11,"Manual"),"")) | D6: =IF(SUMPRODUCT((Log!$B$2:$B$11="myTutor")*(Log!$K$2:$K$11<>""))=0,"",IFERROR(SUMIFS(Log!$K$2:$K$11,Log!$B$2:$B$11,"myTutor")/SUMIFS(Log!$J$2:$J$11,Log!$B$2:$B$11,"myTutor"),"")) | E6: =IF(OR(C6="",D6="",N(C6)=0),"",(D6-C6)/C6) | F6: higher
B7: Links to existing notes per note | C7: =IFERROR(SUMIFS(Log!$M$2:$M$11,Log!$B$2:$B$11,"Manual")/SUMIFS(Log!$J$2:$J$11,Log!$B$2:$B$11,"Manual"),"") | D7: =IFERROR(SUMIFS(Log!$M$2:$M$11,Log!$B$2:$B$11,"myTutor")/SUMIFS(Log!$J$2:$J$11,Log!$B$2:$B$11,"myTutor"),"") | E7: =IF(OR(C7="",D7="",N(C7)=0),"",(D7-C7)/C7) | F7: higher
B8: Total minutes (5 files) | C8: =IF(COUNTIFS(Log!$B$2:$B$11,"Manual",Log!$F$2:$F$11,"<>")=0,"",SUMIFS(Log!$H$2:$H$11,Log!$B$2:$B$11,"Manual")) | D8: =IF(COUNTIFS(Log!$B$2:$B$11,"myTutor",Log!$F$2:$F$11,"<>")=0,"",SUMIFS(Log!$H$2:$H$11,Log!$B$2:$B$11,"myTutor")) | E8: =IF(OR(C8="",D8="",N(C8)=0),"",(D8-C8)/C8) | F8: lower
B10: % change = (myTutor − Manual) ÷ Manual. Fills in automatically from the Log sheet.
B12: Limitations to report
B13: – Only 5 files; time is normalised per 1,000 words.
B14: – Downloading and reading are excluded from both methods, as they are identical.
B15: – A saved prompt was pasted, so manual times are likely faster than usual: any saving is cautious.
B16: – Times and checks are self-recorded.
B17: – myTutor review = 15 s/note (stopwatch average over 5 files), a spot-check not a full read; at 30 s/note the saving is still −54%; break-even 1.2 min/note.
